<?xml version="1.0"?>
<robot name="robot">	
	<material name="yellow">
		<color rgba="0.8 0.8 0 1"/>
	</material>

	<material name="lightgray">
		<color rgba="0.7 0.7 0.7 1"/>
	</material>

	<material name="darkgray">
		<color rgba="0.3 0.3 0.3 1.0"/>
	</material>

	<material name="black">
		<color rgba="0 0 0 1.0"/>
	</material>

	<link name="base_footprint"/>

	<link name="base_link">
		<visual>
			<geometry>
				<box size="0.360 0.290 0.070"/>
			</geometry>			
			<material name="yellow"/>
		</visual>
		<collision>
			<geometry>
				<box size="0.360 0.290 0.070"/>
			</geometry>
		</collision>
	</link>
	
	<joint name="base_footprint_joint" type="fixed">
		<parent link="base_footprint"/>
		<child link="base_link"/>
		<origin rpy="0 0 0" xyz="0 0 0.035"/>
	</joint>

	<link name="torso">
		<visual>
			<geometry>
				<box size="0.360 0.420 0.120" />
			</geometry>
			<material name="yellow"/>
		</visual>
		<collision>
			<geometry>
				<box size="0.360 0.290 0.070"/>
			</geometry>
		</collision>
	</link>
	
	<joint name="torso_joint" type="fixed">
		<parent link="base_link"/>
		<child link="torso"/>
		<origin rpy="0 0 0" xyz="0 0 0.098"/>
	</joint>

	<link name="l_rear_wheel">
		<visual>
			<geometry>
				<cylinder length="0.065" radius="0.035"/>
			</geometry>
			<material name="darkgray"/>
		</visual>
		<collision>
			<geometry>
				<cylinder length="0.065" radius="0.035"/>
			</geometry>
		</collision>
	</link>

	<joint name="l_rear_wheel_joint" type="continuous">
		<parent link="base_link"/>
		<child link="l_rear_wheel"/>
		<origin xyz="-.1475 .1775 0" rpy="1.57075 0 0" />
		<axis xyz="0 1 0" rpy="0 0 0" />
	</joint>

	<link name="l_front_wheel">
		<visual>
			<geometry>
				<cylinder length="0.065" radius="0.035"/>
			</geometry>
			<material name="darkgray"/>
		</visual>
		<collision>
			<geometry>
				<cylinder length="0.065" radius="0.035"/>
			</geometry>
		</collision>
	</link>

	<joint name="l_front_wheel_joint" type="continuous">
		<parent link="base_link"/>
		<child link="l_front_wheel"/>
		<origin xyz=".1475 .1775 0" rpy="1.57075 0 0"/>
		<axis xyz="0 1 0" rpy="0 0 0" />
		<mimic joint="l_rear_wheel_joint" multplier="1.0" offset="0.0" />
	</joint>

	<link name="l_track">
		<visual>
			<geometry>
				<box size="0.290 0.065 0.070"/>
			</geometry>
			<material name="darkgray"/>
		</visual>
		<collision>
			<geometry>
				<box size="0.290 0.065 0.070"/>
			</geometry>
		</collision>
	</link>

	<joint name="l_track_joint" type="fixed">
		<parent link="base_link"/>
		<child link="l_track"/>
		<origin rpy="0 0 0" xyz="0 0.1775 0"/>
	</joint>

	<link name="r_rear_wheel">
		<visual>
			<geometry>
				<cylinder length="0.065" radius="0.035"/>
			</geometry>
			<material name="darkgray"/>
		</visual>
		<collision>
			<geometry>
				<cylinder length="0.065" radius="0.035"/>
			</geometry>
		</collision>
	</link>

	<joint name="r_rear_wheel_joint" type="continuous">
		<parent link="base_link"/>
		<child link="r_rear_wheel"/>
		<origin xyz="-.1475 -.1775 0" rpy="1.57075 0 0"/>
		<axis xyz="0 1 0" rpy="0 0 0" />
	</joint>

	<link name="r_front_wheel">
		<visual>
			<geometry>
				<cylinder length="0.065" radius="0.035"/>
			</geometry>
			<material name="darkgray"/>
		</visual>
		<collision>
			<geometry>
				<cylinder length="0.065" radius="0.035"/>
			</geometry>
		</collision>
	</link>

	<joint name="r_front_wheel_joint" type="continuous">
		<parent link="base_link"/>
		<child link="r_front_wheel"/>
		<origin xyz=".1475 -.1775 0" rpy="1.57075 0 0" />
		<axis xyz="0 1 0" rpy="0 0 0" />
		<mimic joint="r_rear_wheel_joint" multplier="1.0" offset="0.0" />
	</joint>
	
	<link name="r_track">
		<visual>
			<geometry>
				<box size="0.290 0.065 0.070"/>
			</geometry>
			<material name="darkgray"/>
		</visual>
		<collision>
			<geometry>
				<box size="0.290 0.065 0.070"/>
			</geometry>
		</collision>
	</link>

	<joint name="r_track_joint" type="fixed">
		<parent link="base_link"/>
		<child link="r_track"/>
		<origin rpy="0 0 0" xyz="0 -0.1775 0"/>
	</joint>

<joint name="camera_rgb_joint" type="fixed">
	<origin xyz="0.148 0 0.0965" rpy="0 0 0"/>
	<parent link="torso"/>
	<child link="camera_rgb_frame" />
  </joint>

  <link name="camera_rgb_frame">
      <inertial>
        <mass value="0.001" />
        <origin xyz="0 0 0" />
        <inertia ixx="0.0001" ixy="0.0" ixz="0.0"
                 iyy="0.0001" iyz="0.0"
                 izz="0.0001" />
      </inertial>
  </link>



  <joint name="camera_rgb_optical_joint" type="fixed">
      <origin xyz="0 0 0" rpy="-1.5707 0 -1.5707" />
      <parent link="camera_rgb_frame" />
      <child link="camera_rgb_optical_frame" />
  </joint>

  <link name="camera_rgb_optical_frame">
      <inertial>
        <mass value="0.001" />
        <origin xyz="0 0 0" />
        <inertia ixx="0.0001" ixy="0.0" ixz="0.0"
                 iyy="0.0001" iyz="0.0"
                 izz="0.0001" />
      </inertial>
  </link>

  <joint name="camera_joint" type="fixed">
    <origin xyz="-0.031 -0.0125 -0.016" rpy="0 0 0"/>
    <parent link="camera_rgb_frame"/>
    <child link="camera_link"/>
  </joint>
  
  <link name="camera_link">
    <visual>
	<origin xyz="0 0 0" rpy="0 0 1.5707"/>
	<geometry>
		<mesh filename="package://robot_urdf/meshes/sensors/kinect.dae"/>
	</geometry>
    </visual>
    <collision>
      <origin xyz="0.0 0.0 0.0" rpy="0 0 0"/>
      <geometry>
        <box size="0.07271 0.27794 0.073"/>
      </geometry>
    </collision>
    <inertial>
      <mass value="0.001" />
      <origin xyz="0 0 0" />
      <inertia ixx="0.0001" ixy="0.0" ixz="0.0"
               iyy="0.0001" iyz="0.0"
               izz="0.0001" />
    </inertial>
  </link>
	  
  <!-- The fixed joints & links below are usually published by static_transformers launched by the OpenNi launch 
       files. However, for Gazebo simulation we need them, so we add them here.
       (Hence, don't publish them additionally!) -->
  <joint name="camera_depth_joint" type="fixed">
	  <origin xyz="0 0.0250 0" rpy="0 0 0" />
	  <parent link="camera_rgb_frame" />
	  <child link="camera_depth_frame" />
  </joint>

  <link name="camera_depth_frame">
    <inertial>
      <mass value="0.001" />
      <origin xyz="0 0 0" />
      <inertia ixx="0.0001" ixy="0.0" ixz="0.0"
               iyy="0.0001" iyz="0.0"
               izz="0.0001" />
    </inertial>
  </link>

  <joint name="camera_depth_optical_joint" type="fixed">
	  <origin xyz="0 0 0" rpy="-1.5707 0 -1.5707" />
	  <parent link="camera_depth_frame" />
	  <child link="camera_depth_optical_frame" />
  </joint>

  <link name="camera_depth_optical_frame">
    <inertial>
      <mass value="0.001" />
      <origin xyz="0 0 0" />
      <inertia ixx="0.0001" ixy="0.0" ixz="0.0"
               iyy="0.0001" iyz="0.0"
               izz="0.0001" />
    </inertial>
  </link>
</robot>
